




 83%|██████████████████████████████████████████████████████████████████████████████████████████████████████▌                    | 5/6 [00:23<00:04,  4.77s/it]
  0%|                                                                                                                                   | 0/2 [00:00<?, ?it/s]

 50%|█████████████████████████████████████████████████████████████▌                                                             | 1/2 [00:05<00:05,  5.72s/it]
 50%|█████████████████████████████████████████████████████████████▌                                                             | 1/2 [00:06<00:06,  6.70s/it]





 83%|██████████████████████████████████████████████████████████████████████████████████████████████████████▌                    | 5/6 [00:25<00:04,  4.65s/it]
 83%|██████████████████████████████████████████████████████████████████████████████████████████████████████▌                    | 5/6 [00:26<00:05,  5.35s/it]

 50%|█████████████████████████████████████████████████████████████▌                                                             | 1/2 [00:06<00:06,  6.09s/it]
 50%|█████████████████████████████████████████████████████████████▌                                                             | 1/2 [00:07<00:07,  7.66s/it]
  0%|                                                                                                                                   | 0/6 [00:00<?, ?it/s]
Traceback (most recent call last):
  File "/Users/shamba/anaconda3/lib/python3.11/site-packages/torch/utils/data/dataloader.py", line 1133, in _try_get_data
    data = self._data_queue.get(timeout=timeout)
           ^^^^^^^^^^^^^^^^^^^^^^^^^^^^^^^^^^^^^
  File "/Users/shamba/anaconda3/lib/python3.11/multiprocessing/queues.py", line 113, in get
    if not self._poll(timeout):
           ^^^^^^^^^^^^^^^^^^^
  File "/Users/shamba/anaconda3/lib/python3.11/multiprocessing/connection.py", line 256, in poll
    return self._poll(timeout)
           ^^^^^^^^^^^^^^^^^^^
  File "/Users/shamba/anaconda3/lib/python3.11/multiprocessing/connection.py", line 423, in _poll
    r = wait([self], timeout)
        ^^^^^^^^^^^^^^^^^^^^^
  File "/Users/shamba/anaconda3/lib/python3.11/multiprocessing/connection.py", line 930, in wait
    ready = selector.select(timeout)
            ^^^^^^^^^^^^^^^^^^^^^^^^
  File "/Users/shamba/anaconda3/lib/python3.11/selectors.py", line 415, in select
    fd_event_list = self._selector.poll(timeout)
                    ^^^^^^^^^^^^^^^^^^^^^^^^^^^^
  File "/Users/shamba/anaconda3/lib/python3.11/site-packages/torch/utils/data/_utils/signal_handling.py", line 66, in handler
    _error_if_any_worker_fails()
RuntimeError: DataLoader worker (pid 62057) exited unexpectedly with exit code 1. Details are lost due to multiprocessing. Rerunning with num_workers=0 may give better error trace.
The above exception was the direct cause of the following exception:
Traceback (most recent call last):
  File "/Users/shamba/Desktop/Paper 1 - HAR RL/MarginMultistepCL/double_margin.py", line 281, in <module>
  File "/Users/shamba/Desktop/Paper 1 - HAR RL/MarginMultistepCL/double_margin.py", line 150, in main
  File "/Users/shamba/anaconda3/lib/python3.11/site-packages/tqdm/std.py", line 1178, in __iter__
    for obj in iterable:
  File "/Users/shamba/anaconda3/lib/python3.11/site-packages/torch/utils/data/dataloader.py", line 631, in __next__
    data = self._next_data()
           ^^^^^^^^^^^^^^^^^
  File "/Users/shamba/anaconda3/lib/python3.11/site-packages/torch/utils/data/dataloader.py", line 1329, in _next_data
    idx, data = self._get_data()
                ^^^^^^^^^^^^^^^^
  File "/Users/shamba/anaconda3/lib/python3.11/site-packages/torch/utils/data/dataloader.py", line 1295, in _get_data
    success, data = self._try_get_data()
                    ^^^^^^^^^^^^^^^^^^^^
  File "/Users/shamba/anaconda3/lib/python3.11/site-packages/torch/utils/data/dataloader.py", line 1146, in _try_get_data
    raise RuntimeError(f'DataLoader worker (pid(s) {pids_str}) exited unexpectedly') from e
RuntimeError: DataLoader worker (pid(s) 62057) exited unexpectedly