[34m[1mwandb[39m[22m: [33mWARNING[39m Calling wandb.run.save without any arguments is deprecated.Changes to attributes are automatically persisted.
  0%|                                                                                                                                                                                                                                                                                                                                                                                                                                                                                               | 0/500 [00:59<?, ?it/s]
Traceback (most recent call last):
  File "/Users/shamba/anaconda3/lib/python3.11/site-packages/torch/utils/data/dataloader.py", line 1133, in _try_get_data
    data = self._data_queue.get(timeout=timeout)
           ^^^^^^^^^^^^^^^^^^^^^^^^^^^^^^^^^^^^^
  File "/Users/shamba/anaconda3/lib/python3.11/multiprocessing/queues.py", line 114, in get
    raise Empty
_queue.Empty
The above exception was the direct cause of the following exception:
Traceback (most recent call last):
  File "/Users/shamba/Desktop/Paper 1 - HAR RL/NODATA_MarginMultistepCL/baselines/tnc.py", line 466, in <module>
    main(train_loader, valid_loader, valid_balanced_dataloader, seed)
  File "/Users/shamba/Desktop/Paper 1 - HAR RL/NODATA_MarginMultistepCL/baselines/tnc.py", line 248, in main
    for batch_idx, (time_series, _) in enumerate(train_loader):
  File "/Users/shamba/anaconda3/lib/python3.11/site-packages/torch/utils/data/dataloader.py", line 631, in __next__
    data = self._next_data()
           ^^^^^^^^^^^^^^^^^
  File "/Users/shamba/anaconda3/lib/python3.11/site-packages/torch/utils/data/dataloader.py", line 1329, in _next_data
    idx, data = self._get_data()
                ^^^^^^^^^^^^^^^^
  File "/Users/shamba/anaconda3/lib/python3.11/site-packages/torch/utils/data/dataloader.py", line 1295, in _get_data
    success, data = self._try_get_data()
                    ^^^^^^^^^^^^^^^^^^^^
  File "/Users/shamba/anaconda3/lib/python3.11/site-packages/torch/utils/data/dataloader.py", line 1146, in _try_get_data
    raise RuntimeError(f'DataLoader worker (pid(s) {pids_str}) exited unexpectedly') from e
RuntimeError: DataLoader worker (pid(s) 33282, 33295, 33303, 33311) exited unexpectedly